{
    "CVE_data_meta": {
        "ASSIGNER": "security-advisories@github.com",
        "ID": "CVE-2022-39386",
        "STATE": "PUBLIC",
        "TITLE": "fastify-websocket vulnerable to uncaught exception via crash on malformed packet"
    },
    "affects": {
        "vendor": {
            "vendor_data": [
                {
                    "product": {
                        "product_data": [
                            {
                                "product_name": "fastify-websocket",
                                "version": {
                                    "version_data": [
                                        {
                                            "version_value": ">= 5.0.0, < 5.0.1"
                                        },
                                        {
                                            "version_value": ">= 6.0.0, < 7.1.1"
                                        },
                                        {
                                            "version_value": "<= 4.3.0"
                                        }
                                    ]
                                }
                            }
                        ]
                    },
                    "vendor_name": "fastify"
                }
            ]
        }
    },
    "data_format": "MITRE",
    "data_type": "CVE",
    "data_version": "4.0",
    "description": {
        "description_data": [
            {
                "lang": "eng",
                "value": "@fastify/websocket provides WebSocket support for Fastify. Any application using @fastify/websocket could crash if a specific, malformed packet is sent. All versions of fastify-websocket are also impacted. That module is deprecated, so it will not be patched. This has been patched in version 7.1.1 (fastify v4) and version 5.0.1 (fastify v3). There are currently no known workarounds. However, it should be possible to attach the error handler manually. The recommended path is upgrading to the patched versions."
            }
        ]
    },
    "impact": {
        "cvss": {
            "attackComplexity": "LOW",
            "attackVector": "NETWORK",
            "availabilityImpact": "HIGH",
            "baseScore": 7.5,
            "baseSeverity": "HIGH",
            "confidentialityImpact": "NONE",
            "integrityImpact": "NONE",
            "privilegesRequired": "NONE",
            "scope": "UNCHANGED",
            "userInteraction": "NONE",
            "vectorString": "CVSS:3.1/AV:N/AC:L/PR:N/UI:N/S:U/C:N/I:N/A:H",
            "version": "3.1"
        }
    },
    "problemtype": {
        "problemtype_data": [
            {
                "description": [
                    {
                        "lang": "eng",
                        "value": "CWE-248: Uncaught Exception"
                    }
                ]
            }
        ]
    },
    "references": {
        "reference_data": [
            {
                "name": "https://github.com/fastify/fastify-websocket/security/advisories/GHSA-4pcg-wr6c-h9cq",
                "refsource": "CONFIRM",
                "url": "https://github.com/fastify/fastify-websocket/security/advisories/GHSA-4pcg-wr6c-h9cq"
            }
        ]
    },
    "source": {
        "advisory": "GHSA-4pcg-wr6c-h9cq",
        "discovery": "UNKNOWN"
    }
}