{
    "CVE_data_meta": {
        "ASSIGNER": "security-advisories@github.com",
        "ID": "CVE-2022-35999",
        "STATE": "PUBLIC",
        "TITLE": "`CHECK` fail in `Conv2DBackpropInput` in TensorFlow"
    },
    "affects": {
        "vendor": {
            "vendor_data": [
                {
                    "product": {
                        "product_data": [
                            {
                                "product_name": "tensorflow",
                                "version": {
                                    "version_data": [
                                        {
                                            "version_value": "< 2.7.2"
                                        },
                                        {
                                            "version_value": ">= 2.8.0, < 2.8.1"
                                        },
                                        {
                                            "version_value": ">= 2.9.0, < 2.9.1"
                                        }
                                    ]
                                }
                            }
                        ]
                    },
                    "vendor_name": "tensorflow"
                }
            ]
        }
    },
    "data_format": "MITRE",
    "data_type": "CVE",
    "data_version": "4.0",
    "description": {
        "description_data": [
            {
                "lang": "eng",
                "value": "TensorFlow is an open source platform for machine learning. When `Conv2DBackpropInput` receives empty `out_backprop` inputs (e.g. `[3, 1, 0, 1]`), the current CPU/GPU kernels `CHECK` fail (one with dnnl, the other with cudnn). This can be used to trigger a denial of service attack. We have patched the issue in GitHub commit 27a65a43cf763897fecfa5cdb5cc653fc5dd0346. The fix will be included in TensorFlow 2.10.0. We will also cherrypick this commit on TensorFlow 2.9.1, TensorFlow 2.8.1, and TensorFlow 2.7.2, as these are also affected and still in supported range. There are no known workarounds for this issue."
            }
        ]
    },
    "impact": {
        "cvss": {
            "attackComplexity": "HIGH",
            "attackVector": "NETWORK",
            "availabilityImpact": "HIGH",
            "baseScore": 5.9,
            "baseSeverity": "MEDIUM",
            "confidentialityImpact": "NONE",
            "integrityImpact": "NONE",
            "privilegesRequired": "NONE",
            "scope": "UNCHANGED",
            "userInteraction": "NONE",
            "vectorString": "CVSS:3.1/AV:N/AC:H/PR:N/UI:N/S:U/C:N/I:N/A:H",
            "version": "3.1"
        }
    },
    "problemtype": {
        "problemtype_data": [
            {
                "description": [
                    {
                        "lang": "eng",
                        "value": "CWE-617: Reachable Assertion"
                    }
                ]
            }
        ]
    },
    "references": {
        "reference_data": [
            {
                "name": "https://github.com/tensorflow/tensorflow/security/advisories/GHSA-37jf-mjv6-xfqw",
                "refsource": "CONFIRM",
                "url": "https://github.com/tensorflow/tensorflow/security/advisories/GHSA-37jf-mjv6-xfqw"
            },
            {
                "name": "https://github.com/tensorflow/tensorflow/commit/27a65a43cf763897fecfa5cdb5cc653fc5dd0346",
                "refsource": "MISC",
                "url": "https://github.com/tensorflow/tensorflow/commit/27a65a43cf763897fecfa5cdb5cc653fc5dd0346"
            }
        ]
    },
    "source": {
        "advisory": "GHSA-37jf-mjv6-xfqw",
        "discovery": "UNKNOWN"
    }
}