{
    "CVE_data_meta": {
        "ASSIGNER": "security-advisories@github.com",
        "ID": "CVE-2022-35991",
        "STATE": "PUBLIC",
        "TITLE": "`CHECK` fail in `TensorListScatter` and `TensorListScatterV2` in TensorFlow"
    },
    "affects": {
        "vendor": {
            "vendor_data": [
                {
                    "product": {
                        "product_data": [
                            {
                                "product_name": "tensorflow",
                                "version": {
                                    "version_data": [
                                        {
                                            "version_value": "< 2.7.2"
                                        },
                                        {
                                            "version_value": ">= 2.8.0, < 2.8.1"
                                        },
                                        {
                                            "version_value": ">= 2.9.0, < 2.9.1"
                                        }
                                    ]
                                }
                            }
                        ]
                    },
                    "vendor_name": "tensorflow"
                }
            ]
        }
    },
    "data_format": "MITRE",
    "data_type": "CVE",
    "data_version": "4.0",
    "description": {
        "description_data": [
            {
                "lang": "eng",
                "value": "TensorFlow is an open source platform for machine learning. When `TensorListScatter` and `TensorListScatterV2` receive an `element_shape` of a rank greater than one, they give a `CHECK` fail that can trigger a denial of service attack. We have patched the issue in GitHub commit bb03fdf4aae944ab2e4b35c7daa051068a8b7f61. The fix will be included in TensorFlow 2.10.0. We will also cherrypick this commit on TensorFlow 2.9.1, TensorFlow 2.8.1, and TensorFlow 2.7.2, as these are also affected and still in supported range. There are no known workarounds for this issue."
            }
        ]
    },
    "impact": {
        "cvss": {
            "attackComplexity": "HIGH",
            "attackVector": "NETWORK",
            "availabilityImpact": "HIGH",
            "baseScore": 5.9,
            "baseSeverity": "MEDIUM",
            "confidentialityImpact": "NONE",
            "integrityImpact": "NONE",
            "privilegesRequired": "NONE",
            "scope": "UNCHANGED",
            "userInteraction": "NONE",
            "vectorString": "CVSS:3.1/AV:N/AC:H/PR:N/UI:N/S:U/C:N/I:N/A:H",
            "version": "3.1"
        }
    },
    "problemtype": {
        "problemtype_data": [
            {
                "description": [
                    {
                        "lang": "eng",
                        "value": "CWE-617: Reachable Assertion"
                    }
                ]
            }
        ]
    },
    "references": {
        "reference_data": [
            {
                "name": "https://github.com/tensorflow/tensorflow/security/advisories/GHSA-vm7x-4qhj-rrcq",
                "refsource": "CONFIRM",
                "url": "https://github.com/tensorflow/tensorflow/security/advisories/GHSA-vm7x-4qhj-rrcq"
            },
            {
                "name": "https://github.com/tensorflow/tensorflow/commit/bb03fdf4aae944ab2e4b35c7daa051068a8b7f61",
                "refsource": "MISC",
                "url": "https://github.com/tensorflow/tensorflow/commit/bb03fdf4aae944ab2e4b35c7daa051068a8b7f61"
            }
        ]
    },
    "source": {
        "advisory": "GHSA-vm7x-4qhj-rrcq",
        "discovery": "UNKNOWN"
    }
}