{
    "CVE_data_meta": {
        "ASSIGNER": "security-advisories@github.com",
        "ID": "CVE-2021-29551",
        "STATE": "PUBLIC",
        "TITLE": "OOB read in `MatrixTriangularSolve`"
    },
    "affects": {
        "vendor": {
            "vendor_data": [
                {
                    "product": {
                        "product_data": [
                            {
                                "product_name": "tensorflow",
                                "version": {
                                    "version_data": [
                                        {
                                            "version_value": "< 2.1.4"
                                        },
                                        {
                                            "version_value": ">= 2.2.0, < 2.2.3"
                                        },
                                        {
                                            "version_value": ">= 2.3.0, < 2.3.3"
                                        },
                                        {
                                            "version_value": ">= 2.4.0, < 2.4.2"
                                        }
                                    ]
                                }
                            }
                        ]
                    },
                    "vendor_name": "tensorflow"
                }
            ]
        }
    },
    "data_format": "MITRE",
    "data_type": "CVE",
    "data_version": "4.0",
    "description": {
        "description_data": [
            {
                "lang": "eng",
                "value": "TensorFlow is an end-to-end open source platform for machine learning. The implementation of `MatrixTriangularSolve`(https://github.com/tensorflow/tensorflow/blob/8cae746d8449c7dda5298327353d68613f16e798/tensorflow/core/kernels/linalg/matrix_triangular_solve_op_impl.h#L160-L240) fails to terminate kernel execution if one validation condition fails. The fix will be included in TensorFlow 2.5.0. We will also cherrypick this commit on TensorFlow 2.4.2, TensorFlow 2.3.3, TensorFlow 2.2.3 and TensorFlow 2.1.4, as these are also affected and still in supported range."
            }
        ]
    },
    "impact": {
        "cvss": {
            "attackComplexity": "HIGH",
            "attackVector": "LOCAL",
            "availabilityImpact": "LOW",
            "baseScore": 2.5,
            "baseSeverity": "LOW",
            "confidentialityImpact": "NONE",
            "integrityImpact": "NONE",
            "privilegesRequired": "LOW",
            "scope": "UNCHANGED",
            "userInteraction": "NONE",
            "vectorString": "CVSS:3.1/AV:L/AC:H/PR:L/UI:N/S:U/C:N/I:N/A:L",
            "version": "3.1"
        }
    },
    "problemtype": {
        "problemtype_data": [
            {
                "description": [
                    {
                        "lang": "eng",
                        "value": "CWE-125: Out-of-bounds Read"
                    }
                ]
            }
        ]
    },
    "references": {
        "reference_data": [
            {
                "name": "https://github.com/tensorflow/tensorflow/security/advisories/GHSA-vqw6-72r7-fgw7",
                "refsource": "CONFIRM",
                "url": "https://github.com/tensorflow/tensorflow/security/advisories/GHSA-vqw6-72r7-fgw7"
            },
            {
                "name": "https://github.com/tensorflow/tensorflow/commit/480641e3599775a8895254ffbc0fc45621334f68",
                "refsource": "MISC",
                "url": "https://github.com/tensorflow/tensorflow/commit/480641e3599775a8895254ffbc0fc45621334f68"
            }
        ]
    },
    "source": {
        "advisory": "GHSA-vqw6-72r7-fgw7",
        "discovery": "UNKNOWN"
    }
}